INFO:     Started server process [2154]
INFO:     Waiting for application startup.
INFO:     Application startup complete.
INFO:     Uvicorn running on http://127.0.0.1:8000 (Press CTRL+C to quit)
INFO:     127.0.0.1:40746 - "POST /webhook HTTP/1.1" 500 Internal Server Error
ERROR:    Exception in ASGI application
Traceback (most recent call last):
  File "/root/Luminara_bot/venv/lib/python3.10/site-packages/uvicorn/protocols/http/h11_impl.py", line 403, in run_asgi
    result = await app(  # type: ignore[func-returns-value]
  File "/root/Luminara_bot/venv/lib/python3.10/site-packages/uvicorn/middleware/proxy_headers.py", line 60, in __call__
    return await self.app(scope, receive, send)
  File "/root/Luminara_bot/venv/lib/python3.10/site-packages/fastapi/applications.py", line 1054, in __call__
    await super().__call__(scope, receive, send)
  File "/root/Luminara_bot/venv/lib/python3.10/site-packages/starlette/applications.py", line 112, in __call__
    await self.middleware_stack(scope, receive, send)
  File "/root/Luminara_bot/venv/lib/python3.10/site-packages/starlette/middleware/errors.py", line 187, in __call__
    raise exc
  File "/root/Luminara_bot/venv/lib/python3.10/site-packages/starlette/middleware/errors.py", line 165, in __call__
    await self.app(scope, receive, _send)
  File "/root/Luminara_bot/venv/lib/python3.10/site-packages/starlette/middleware/exceptions.py", line 62, in __call__
    await wrap_app_handling_exceptions(self.app, conn)(scope, receive, send)
  File "/root/Luminara_bot/venv/lib/python3.10/site-packages/starlette/_exception_handler.py", line 53, in wrapped_app
    raise exc
  File "/root/Luminara_bot/venv/lib/python3.10/site-packages/starlette/_exception_handler.py", line 42, in wrapped_app
    await app(scope, receive, sender)
  File "/root/Luminara_bot/venv/lib/python3.10/site-packages/starlette/routing.py", line 714, in __call__
    await self.middleware_stack(scope, receive, send)
  File "/root/Luminara_bot/venv/lib/python3.10/site-packages/starlette/routing.py", line 734, in app
    await route.handle(scope, receive, send)
  File "/root/Luminara_bot/venv/lib/python3.10/site-packages/starlette/routing.py", line 288, in handle
    await self.app(scope, receive, send)
  File "/root/Luminara_bot/venv/lib/python3.10/site-packages/starlette/routing.py", line 76, in app
    await wrap_app_handling_exceptions(app, request)(scope, receive, send)
  File "/root/Luminara_bot/venv/lib/python3.10/site-packages/starlette/_exception_handler.py", line 53, in wrapped_app
    raise exc
  File "/root/Luminara_bot/venv/lib/python3.10/site-packages/starlette/_exception_handler.py", line 42, in wrapped_app
    await app(scope, receive, sender)
  File "/root/Luminara_bot/venv/lib/python3.10/site-packages/starlette/routing.py", line 73, in app
    response = await f(request)
  File "/root/Luminara_bot/venv/lib/python3.10/site-packages/fastapi/routing.py", line 301, in app
    raw_response = await run_endpoint_function(
  File "/root/Luminara_bot/venv/lib/python3.10/site-packages/fastapi/routing.py", line 212, in run_endpoint_function
    return await dependant.call(**values)
  File "/root/Luminara_bot/main.py", line 11, in webhook
    return await handle_update(data)
  File "/root/Luminara_bot/app/handlers.py", line 26, in handle_update
    forecast = get_forecast(numbers)
  File "/root/Luminara_bot/app/ai_client.py", line 22, in get_forecast
    resp = client.chat.completions.create(
  File "/root/Luminara_bot/venv/lib/python3.10/site-packages/openai/_utils/_utils.py", line 287, in wrapper
    return func(*args, **kwargs)
  File "/root/Luminara_bot/venv/lib/python3.10/site-packages/openai/resources/chat/completions/completions.py", line 925, in create
    return self._post(
  File "/root/Luminara_bot/venv/lib/python3.10/site-packages/openai/_base_client.py", line 1239, in post
    return cast(ResponseT, self.request(cast_to, opts, stream=stream, stream_cls=stream_cls))
  File "/root/Luminara_bot/venv/lib/python3.10/site-packages/openai/_base_client.py", line 1034, in request
    raise self._make_status_error_from_response(err.response) from None
openai.PermissionDeniedError: Error code: 403 - {'error': {'code': 'unsupported_country_region_territory', 'message': 'Country, region, or territory not supported', 'param': None, 'type': 'request_forbidden'}}
